2020-06-12 07:52:45,363 ERROR: Exception on /auth/reset_password_request [POST] [in c:\python\python37\lib\site-packages\flask\app.py:1892]
Traceback (most recent call last):
  File "c:\python\python37\lib\site-packages\flask\app.py", line 2447, in wsgi_app
    response = self.full_dispatch_request()
  File "c:\python\python37\lib\site-packages\flask\app.py", line 1952, in full_dispatch_request
    rv = self.handle_user_exception(e)
  File "c:\python\python37\lib\site-packages\flask\app.py", line 1821, in handle_user_exception
    reraise(exc_type, exc_value, tb)
  File "c:\python\python37\lib\site-packages\flask\_compat.py", line 39, in reraise
    raise value
  File "c:\python\python37\lib\site-packages\flask\app.py", line 1950, in full_dispatch_request
    rv = self.dispatch_request()
  File "c:\python\python37\lib\site-packages\flask\app.py", line 1936, in dispatch_request
    return self.view_functions[rule.endpoint](**req.view_args)
  File "E:\Flask\microblog\app\auth\routes.py", line 87, in reset_password_request
    send_password_reset_email(user)
  File "E:\Flask\microblog\app\auth\email.py", line 14, in send_password_reset_email
    user=user, token=token),
  File "c:\python\python37\lib\site-packages\flask\templating.py", line 140, in render_template
    ctx.app,
  File "c:\python\python37\lib\site-packages\flask\templating.py", line 120, in _render
    rv = template.render(context)
  File "c:\python\python37\lib\site-packages\jinja2\environment.py", line 1090, in render
    self.environment.handle_exception()
  File "c:\python\python37\lib\site-packages\jinja2\environment.py", line 832, in handle_exception
    reraise(*rewrite_traceback_stack(source=source))
  File "c:\python\python37\lib\site-packages\jinja2\_compat.py", line 28, in reraise
    raise value.with_traceback(tb)
  File "E:\Flask\microblog\app\templates\email\reset_password.txt", line 5, in top-level template code
    {{ url_for('reset_password', token=token, _external=True) }}
  File "c:\python\python37\lib\site-packages\flask\helpers.py", line 370, in url_for
    return appctx.app.handle_url_build_error(error, endpoint, values)
  File "c:\python\python37\lib\site-packages\flask\app.py", line 2216, in handle_url_build_error
    reraise(exc_type, exc_value, tb)
  File "c:\python\python37\lib\site-packages\flask\_compat.py", line 39, in reraise
    raise value
  File "c:\python\python37\lib\site-packages\flask\helpers.py", line 358, in url_for
    endpoint, values, method=method, force_external=external
  File "c:\python\python37\lib\site-packages\werkzeug\routing.py", line 2179, in build
    raise BuildError(endpoint, values, method, self)
werkzeug.routing.BuildError: Could not build url for endpoint 'reset_password' with values ['token']. Did you mean 'auth.reset_password' instead?
2020-06-12 07:55:44,476 INFO: Microblog startup [in E:\Flask\microblog\app\__init__.py:85]
2020-06-12 07:56:49,186 INFO: Microblog startup [in E:\Flask\microblog\app\__init__.py:85]
2020-06-12 07:57:47,594 INFO: Microblog startup [in E:\Flask\microblog\app\__init__.py:85]
2020-06-12 07:59:32,837 INFO: Microblog startup [in E:\Flask\microblog\app\__init__.py:85]
2020-06-12 08:02:41,168 INFO: Microblog startup [in E:\Flask\microblog\app\__init__.py:85]
2020-06-12 08:08:46,601 INFO: Microblog startup [in E:\Flask\microblog\app\__init__.py:85]
2020-06-12 08:09:07,100 ERROR: Exception on /auth/reset_password_request [POST] [in c:\python\python37\lib\site-packages\flask\app.py:1892]
Traceback (most recent call last):
  File "c:\python\python37\lib\site-packages\flask\app.py", line 2447, in wsgi_app
    response = self.full_dispatch_request()
  File "c:\python\python37\lib\site-packages\flask\app.py", line 1952, in full_dispatch_request
    rv = self.handle_user_exception(e)
  File "c:\python\python37\lib\site-packages\flask\app.py", line 1821, in handle_user_exception
    reraise(exc_type, exc_value, tb)
  File "c:\python\python37\lib\site-packages\flask\_compat.py", line 39, in reraise
    raise value
  File "c:\python\python37\lib\site-packages\flask\app.py", line 1950, in full_dispatch_request
    rv = self.dispatch_request()
  File "c:\python\python37\lib\site-packages\flask\app.py", line 1936, in dispatch_request
    return self.view_functions[rule.endpoint](**req.view_args)
  File "E:\Flask\microblog\app\auth\routes.py", line 88, in reset_password_request
    send_password_reset_email(user)
  File "E:\Flask\microblog\app\auth\email.py", line 14, in send_password_reset_email
    user=user, token=token),
  File "c:\python\python37\lib\site-packages\flask\templating.py", line 140, in render_template
    ctx.app,
  File "c:\python\python37\lib\site-packages\flask\templating.py", line 120, in _render
    rv = template.render(context)
  File "c:\python\python37\lib\site-packages\jinja2\environment.py", line 1090, in render
    self.environment.handle_exception()
  File "c:\python\python37\lib\site-packages\jinja2\environment.py", line 832, in handle_exception
    reraise(*rewrite_traceback_stack(source=source))
  File "c:\python\python37\lib\site-packages\jinja2\_compat.py", line 28, in reraise
    raise value.with_traceback(tb)
  File "E:\Flask\microblog\app\templates\email\reset_password.txt", line 5, in top-level template code
    {{ url_for('reset_password', token=token, _external=True) }}
  File "c:\python\python37\lib\site-packages\flask\helpers.py", line 370, in url_for
    return appctx.app.handle_url_build_error(error, endpoint, values)
  File "c:\python\python37\lib\site-packages\flask\app.py", line 2216, in handle_url_build_error
    reraise(exc_type, exc_value, tb)
  File "c:\python\python37\lib\site-packages\flask\_compat.py", line 39, in reraise
    raise value
  File "c:\python\python37\lib\site-packages\flask\helpers.py", line 358, in url_for
    endpoint, values, method=method, force_external=external
  File "c:\python\python37\lib\site-packages\werkzeug\routing.py", line 2179, in build
    raise BuildError(endpoint, values, method, self)
werkzeug.routing.BuildError: Could not build url for endpoint 'reset_password' with values ['token']. Did you mean 'auth.reset_password' instead?
2020-06-12 08:10:34,211 INFO: Microblog startup [in E:\Flask\microblog\app\__init__.py:85]
2020-06-12 08:11:33,913 INFO: Microblog startup [in E:\Flask\microblog\app\__init__.py:85]
2020-06-12 08:14:24,533 INFO: Microblog startup [in E:\Flask\microblog\app\__init__.py:85]
2020-06-12 08:16:05,817 INFO: Microblog startup [in E:\Flask\microblog\app\__init__.py:85]
2020-06-12 08:27:10,672 INFO: Microblog startup [in E:\Flask\microblog\app\__init__.py:85]
2020-06-12 08:27:43,761 ERROR: Exception on /auth/reset_password_request [POST] [in c:\python\python37\lib\site-packages\flask\app.py:1892]
Traceback (most recent call last):
  File "c:\python\python37\lib\site-packages\flask\app.py", line 2447, in wsgi_app
    response = self.full_dispatch_request()
  File "c:\python\python37\lib\site-packages\flask\app.py", line 1952, in full_dispatch_request
    rv = self.handle_user_exception(e)
  File "c:\python\python37\lib\site-packages\flask\app.py", line 1821, in handle_user_exception
    reraise(exc_type, exc_value, tb)
  File "c:\python\python37\lib\site-packages\flask\_compat.py", line 39, in reraise
    raise value
  File "c:\python\python37\lib\site-packages\flask\app.py", line 1950, in full_dispatch_request
    rv = self.dispatch_request()
  File "c:\python\python37\lib\site-packages\flask\app.py", line 1936, in dispatch_request
    return self.view_functions[rule.endpoint](**req.view_args)
  File "E:\Flask\microblog\app\auth\routes.py", line 88, in reset_password_request
    send_password_reset_email(user)
  File "E:\Flask\microblog\app\auth\email.py", line 15, in send_password_reset_email
    user=user, token=token),
  File "c:\python\python37\lib\site-packages\flask\templating.py", line 140, in render_template
    ctx.app,
  File "c:\python\python37\lib\site-packages\flask\templating.py", line 120, in _render
    rv = template.render(context)
  File "c:\python\python37\lib\site-packages\jinja2\environment.py", line 1090, in render
    self.environment.handle_exception()
  File "c:\python\python37\lib\site-packages\jinja2\environment.py", line 832, in handle_exception
    reraise(*rewrite_traceback_stack(source=source))
  File "c:\python\python37\lib\site-packages\jinja2\_compat.py", line 28, in reraise
    raise value.with_traceback(tb)
  File "E:\Flask\microblog\app\templates\email\reset_password.txt", line 5, in top-level template code
    {{ url_for('reset_password', token=token, _external=True) }}
  File "c:\python\python37\lib\site-packages\flask\helpers.py", line 370, in url_for
    return appctx.app.handle_url_build_error(error, endpoint, values)
  File "c:\python\python37\lib\site-packages\flask\app.py", line 2216, in handle_url_build_error
    reraise(exc_type, exc_value, tb)
  File "c:\python\python37\lib\site-packages\flask\_compat.py", line 39, in reraise
    raise value
  File "c:\python\python37\lib\site-packages\flask\helpers.py", line 358, in url_for
    endpoint, values, method=method, force_external=external
  File "c:\python\python37\lib\site-packages\werkzeug\routing.py", line 2179, in build
    raise BuildError(endpoint, values, method, self)
werkzeug.routing.BuildError: Could not build url for endpoint 'reset_password' with values ['token']. Did you mean 'auth.reset_password' instead?
2020-06-12 08:43:28,090 INFO: Microblog startup [in E:\Flask\microblog\app\__init__.py:85]
2020-06-12 08:44:05,660 INFO: Microblog startup [in E:\Flask\microblog\app\__init__.py:85]
2020-06-12 08:46:35,686 INFO: Microblog startup [in E:\Flask\microblog\app\__init__.py:85]
2020-06-12 08:50:13,346 INFO: Microblog startup [in E:\Flask\microblog\app\__init__.py:85]
2020-06-12 08:53:04,676 INFO: Microblog startup [in E:\Flask\microblog\app\__init__.py:85]
2020-06-12 08:55:04,992 INFO: Microblog startup [in E:\Flask\microblog\app\__init__.py:85]
